#VRML_SIM R2021b utf8
WorldInfo {
  coordinateSystem "NUE"
}
Viewpoint {
  orientation -0.11944760591625589 0.9854352511817539 0.12103567725769321 1.5470370512268048
  position 5.2092110204236235 2.5909413518770363 0.18645230807167226
}
TexturedBackground {
}
TexturedBackgroundLight {
}
RectangleArena {
  floorSize 3 3
  wallHeight 0.0001
}
Robot {
  translation 0 0.75 0
  children [
    DEF sh Shape {
      appearance PBRAppearance {
        metalness 0
      }
      geometry Box {
        size 1 1.5 1
      }
    }
    HingeJoint {
      jointParameters HingeJointParameters {
        anchor 0.59 0.74 3.7543e-07
      }
      device [
        RotationalMotor {
          name "left wheel motor"
        }
      ]
      endPoint Solid {
        translation 0.59 0.74 3.7543e-07
        rotation 2.346409999987081e-06 -2.346409999987081e-06 0.9999999999944944 1.5708
        children [
          DEF s Shape {
            appearance PBRAppearance {
              metalness 0
            }
            geometry Cylinder {
              height 0.1
            }
          }
          Solid {
            translation 0.89 -0.09 0
            children [
              DEF p Shape {
                appearance PBRAppearance {
                  metalness 0
                }
                geometry Capsule {
                  height 0.2
                  radius 0.02
                }
              }
            ]
            boundingObject USE p
            physics Physics {
              density 10
            }
          }
        ]
        boundingObject USE s
        physics Physics {
          density 10
        }
      }
    }
  ]
  boundingObject USE sh
  physics Physics {
    density 10
  }
  controller "my_controller"
}
Solid {
  translation 0.82 2.16 0
  children [
    DEF pk Shape {
      appearance PBRAppearance {
        baseColor 0 1 1
        metalness 0
      }
      geometry Box {
        size 0.3 0.3 0.3
      }
    }
    Solid {
      translation -0.08 0.24928 0.05
      rotation 1 0 0 -0.523595307179586
      children [
        DEF e Shape {
          appearance PBRAppearance {
            baseColor 0 1 1
            metalness 0
          }
          geometry Cylinder {
            height 0.3
            radius 0.01
          }
        }
        Solid {
          translation 0 0.0467 -0.0789221
          rotation 1 0 0 1.0472
          children [
            DEF e Shape {
              appearance PBRAppearance {
                baseColor 0 1 1
                metalness 0
              }
              geometry Cylinder {
                height 0.3
                radius 0.01
              }
            }
          ]
          boundingObject USE e
          physics Physics {
            density 100
          }
        }
      ]
      boundingObject USE e
      physics Physics {
        density 100
      }
    }
  ]
  boundingObject USE pk
  physics Physics {
    density 10
  }
}
